<?xml version="1.0" ?>
<robot name="diff_drive" xmlns:xacro="http://www.ros.org/wiki/xacro">

<xacro:include filename="$(find nav2_outdoor_example)/urdf/materials.xacro" />
<xacro:include filename="$(find nav2_outdoor_example)/urdf/robot.gazebo" />

<link name="base_link">
  <inertial>
    <origin xyz="0 0 0" rpy="0 0 0"/>
    <mass value="97.36517446475621"/>
    <inertia ixx="8.084237" iyy="15.065847" izz="23.090003" ixy="-0.0" iyz="-0.0" ixz="0.0"/>
  </inertial>
  <visual>
    <origin xyz="0 0 0" rpy="0 0 0"/>
    <geometry>
      <mesh filename="file://$(find nav2_outdoor_example)/urdf/meshes/base_link.stl" scale="0.001 0.001 0.001"/>
    </geometry>
    <material name="blue"/>
  </visual>
  <collision>
    <origin xyz="0 0 0" rpy="0 0 0"/>
    <geometry>
      <mesh filename="file://$(find nav2_outdoor_example)/urdf/meshes/base_link.stl" scale="0.001 0.001 0.001"/>
    </geometry>
  </collision>
</link>

<link name="rear_right">
  <inertial>
    <origin xyz="0.029227848902287357 0.05062404177426588 0" rpy="0 0 0"/>
    <mass value="23.230413890431347"/>
    <inertia ixx="0.212208" iyy="0.290082" izz="0.17327" ixy="0.067441" iyz="0.0" ixz="-0.0"/>
  </inertial>
  <visual>
    <origin xyz="0.35 0.233285 0.0" rpy="0 0 0"/>
    <geometry>
      <mesh filename="file://$(find nav2_outdoor_example)/urdf/meshes/wheel_1_1.stl" scale="0.001 0.001 0.001"/>
    </geometry>
    <material name="silver"/>
  </visual>
  <collision>
    <origin xyz="0.35 0.233285 0.0" rpy="0 0 0"/>
    <geometry>
      <mesh filename="file://$(find nav2_outdoor_example)/urdf/meshes/wheel_1_1.stl" scale="0.001 0.001 0.001"/>
    </geometry>
  </collision>
</link>

<link name="rear_left">
  <inertial>
    <origin xyz="0.029227848902285802 -0.050623764868230586 0" rpy="0 0 0"/>
    <mass value="23.230413890431347"/>
    <inertia ixx="0.212208" iyy="0.290082" izz="0.17327" ixy="-0.067441" iyz="-0.0" ixz="0.0"/>
  </inertial>
  <visual>
    <origin xyz="0.35 -0.233285 0.0" rpy="0 0 0"/>
    <geometry>
      <mesh filename="file://$(find nav2_outdoor_example)/urdf/meshes/wheel_2_1.stl" scale="0.001 0.001 0.001"/>
    </geometry>
    <material name="silver"/>
  </visual>
  <collision>
    <origin xyz="0.35 -0.233285 0.0" rpy="0 0 0"/>
    <geometry>
      <mesh filename="file://$(find nav2_outdoor_example)/urdf/meshes/wheel_2_1.stl" scale="0.001 0.001 0.001"/>
    </geometry>
  </collision>
</link>

<link name="front_left">
  <inertial>
    <origin xyz="-0.02922784890228497 -0.05062376486823089 0" rpy="0 0 0"/>
    <mass value="23.230413890431347"/>
    <inertia ixx="0.212208" iyy="0.290082" izz="0.17327" ixy="0.067441" iyz="-0.0" ixz="-0.0"/>
  </inertial>
  <visual>
    <origin xyz="-0.35 -0.233285 0.0" rpy="0 0 0"/>
    <geometry>
      <mesh filename="file://$(find nav2_outdoor_example)/urdf/meshes/wheel_4_1.stl" scale="0.001 0.001 0.001"/>
    </geometry>
    <material name="silver"/>
  </visual>
  <collision>
    <origin xyz="-0.35 -0.233285 0.0" rpy="0 0 0"/>
    <geometry>
      <mesh filename="file://$(find nav2_outdoor_example)/urdf/meshes/wheel_4_1.stl" scale="0.001 0.001 0.001"/>
    </geometry>
  </collision>
</link>

<link name="front_right">
  <inertial>
    <origin xyz="-0.0292278489022878 0.05062404177426641 0" rpy="0 0 0"/>
    <mass value="23.230413890431347"/>
    <inertia ixx="0.212208" iyy="0.290082" izz="0.17327" ixy="-0.067441" iyz="0.0" ixz="-0.0"/>
  </inertial>
  <visual>
    <origin xyz="-0.35 0.233285 0.0" rpy="0 0 0"/>
    <geometry>
      <mesh filename="file://$(find nav2_outdoor_example)/urdf/meshes/wheel_3_1.stl" scale="0.001 0.001 0.001"/>
    </geometry>
    <material name="silver"/>
  </visual>
  <collision>
    <origin xyz="-0.35 0.233285 0.0" rpy="0 0 0"/>
    <geometry>
      <mesh filename="file://$(find nav2_outdoor_example)/urdf/meshes/wheel_3_1.stl" scale="0.001 0.001 0.001"/>
    </geometry>
  </collision>
</link>

<joint name="rear_right_joint" type="continuous">
  <origin xyz="-0.35 -0.233285 0.0" rpy="0 0 0"/>
  <parent link="base_link"/>
  <child link="rear_right"/>
  <axis xyz="0.5 0.866025 -0.0"/>
</joint>

<joint name="rear_left_joint" type="continuous">
  <origin xyz="-0.35 0.233285 0.0" rpy="0 0 0"/>
  <parent link="base_link"/>
  <child link="rear_left"/>
  <axis xyz="-0.5 0.866025 0.0"/>
</joint>

<joint name="front_left_joint" type="continuous">
  <origin xyz="0.35 0.233285 0.0" rpy="0 0 0"/>
  <parent link="base_link"/>
  <child link="front_left"/>
  <axis xyz="0.5 0.866025 0.0"/>
</joint>

<joint name="front_right_joint" type="continuous">
  <origin xyz="0.35 -0.233285 0.0" rpy="0 0 0"/>
  <parent link="base_link"/>
  <child link="front_right"/>
  <axis xyz="-0.5 0.866025 -0.0"/>
</joint>

</robot>
